<?xml version="1.0" ?>
<!-- =================================================================================== -->
<!-- |    This document was autogenerated by xacro from snakebot.urdf.xacro            | -->
<!-- |    EDITING THIS FILE BY HAND IS NOT RECOMMENDED                                 | -->
<!-- =================================================================================== -->
<robot name="snakebot" xmlns:xacro="http://ros.org/wiki/xacro">
  <!-- constants -->
  <!-- arbitrary value for link mass -->
  <!-- Square dimensions of links -->
  <!-- Square dimensions of links -->
  <!-- macros -->
  <!-- joint -->
  <!-- head link (GoPro) -->
  <link name="camera_link">
    <visual>
      <geometry>
        <mesh filename="package://snakebot_description/meshes/DAE/head_link.dae"/>
      </geometry>
    </visual>
    <!-- ====== for Gazebo ======  -->
    <collision>
      <geometry>
        <mesh filename="package://snakebot_description/meshes/DAE/head_link.dae"/>
      </geometry>
    </collision>
    <inertial>
      <mass value="0.1"/>
      <inertia ixx="1.0" ixy="0.0" ixz="0.0" iyy="1.0" iyz="0.0" izz="1.0"/>
    </inertial>
    <!-- == == == == == == == == == -->
  </link>
  <!--  joints -->
  <joint name="joint0" type="revolute">
    <parent link="link0"/>
    <child link="camera_link"/>
    <origin xyz="0 0 0"/>
    <axis xyz="0 0 1"/>
    <limit effort="30" lower="-1.3" upper="1.3" velocity="1.571"/>
    <dynamics damping="0.7"/>
  </joint>
  <!-- Tail link -->
  <link name="tail_link">
    <visual>
      <geometry>
        <mesh filename="package://snakebot_description/meshes/DAE/tail_link.dae"/>
      </geometry>
    </visual>
    <!-- ======= for Gazebo ====== -->
    <collision>
      <geometry>
        <mesh filename="package://snakebot_description/meshes/DAE/tail_link.dae"/>
      </geometry>
    </collision>
    <inertial>
      <mass value="0.1"/>
      <inertia ixx="1.0" ixy="0.0" ixz="0.0" iyy="1.0" iyz="0.0" izz="1.0"/>
    </inertial>
    <!-- == == == == == == == == == -->
  </link>
  <!--  joints -->
  <joint name="joint19" type="revolute">
    <parent link="link18"/>
    <child link="tail_link"/>
    <origin xyz="-0.09 0 0"/>
    <axis xyz="0 1 0"/>
    <limit effort="30" lower="-1.3" upper="1.3" velocity="1.571"/>
    <dynamics damping="0.7"/>
  </joint>
  <!-- body units -->
  <link name="link0">
    <visual>
      <geometry>
        <mesh filename="package://snakebot_description/meshes/DAE/pitch_motor_link2.dae"/>
      </geometry>
    </visual>
    <!-- ====== for Gazebo ====== -->
    <collision>
      <geometry>
        <mesh filename="package://snakebot_description/meshes/DAE/pitch_motor_link2.dae"/>
      </geometry>
    </collision>
    <inertial>
      <mass value="0.1"/>
      <inertia ixx="1.0" ixy="0.0" ixz="0.0" iyy="1.0" iyz="0.0" izz="1.0"/>
    </inertial>
    <!-- == == == == == == == == == -->
  </link>
  <joint name="joint1" type="revolute">
    <parent link="link0"/>
    <child link="link1"/>
    <origin xyz="-0.09 0 0"/>
    <axis xyz="0 1 0"/>
    <!-- ====== for Gazebo  ======  -->
    <limit effort="30" lower="-1.3" upper="1.3" velocity="1.571"/>
    <dynamics damping="0.7"/>
    <!-- == == == == == == == == == -->
  </joint>
  <link name="link1">
    <visual>
      <geometry>
        <mesh filename="package://snakebot_description/meshes/DAE/yaw_motor_link2.dae"/>
      </geometry>
    </visual>
    <!-- ====== for Gazebo ====== -->
    <collision>
      <geometry>
        <mesh filename="package://snakebot_description/meshes/DAE/yaw_motor_link2.dae"/>
      </geometry>
    </collision>
    <inertial>
      <mass value="0.1"/>
      <inertia ixx="1.0" ixy="0.0" ixz="0.0" iyy="1.0" iyz="0.0" izz="1.0"/>
    </inertial>
    <!-- == == == == == == == == == -->
  </link>
  <joint name="joint2" type="revolute">
    <parent link="link1"/>
    <child link="link2"/>
    <origin xyz="-0.09 0 0"/>
    <axis xyz="0 0 1"/>
    <!-- ====== for Gazebo  ======  -->
    <limit effort="30" lower="-1.3" upper="1.3" velocity="1.571"/>
    <dynamics damping="0.7"/>
    <!-- == == == == == == == == == -->
  </joint>
  <link name="link2">
    <visual>
      <geometry>
        <mesh filename="package://snakebot_description/meshes/DAE/pitch_motor_link2.dae"/>
      </geometry>
    </visual>
    <!-- ====== for Gazebo ====== -->
    <collision>
      <geometry>
        <mesh filename="package://snakebot_description/meshes/DAE/pitch_motor_link2.dae"/>
      </geometry>
    </collision>
    <inertial>
      <mass value="0.1"/>
      <inertia ixx="1.0" ixy="0.0" ixz="0.0" iyy="1.0" iyz="0.0" izz="1.0"/>
    </inertial>
    <!-- == == == == == == == == == -->
  </link>
  <joint name="joint3" type="revolute">
    <parent link="link2"/>
    <child link="link3"/>
    <origin xyz="-0.09 0 0"/>
    <axis xyz="0 1 0"/>
    <!-- ====== for Gazebo  ======  -->
    <limit effort="30" lower="-1.3" upper="1.3" velocity="1.571"/>
    <dynamics damping="0.7"/>
    <!-- == == == == == == == == == -->
  </joint>
  <link name="link3">
    <visual>
      <geometry>
        <mesh filename="package://snakebot_description/meshes/DAE/yaw_motor_link2.dae"/>
      </geometry>
    </visual>
    <!-- ====== for Gazebo ====== -->
    <collision>
      <geometry>
        <mesh filename="package://snakebot_description/meshes/DAE/yaw_motor_link2.dae"/>
      </geometry>
    </collision>
    <inertial>
      <mass value="0.1"/>
      <inertia ixx="1.0" ixy="0.0" ixz="0.0" iyy="1.0" iyz="0.0" izz="1.0"/>
    </inertial>
    <!-- == == == == == == == == == -->
  </link>
  <joint name="joint4" type="revolute">
    <parent link="link3"/>
    <child link="link4"/>
    <origin xyz="-0.09 0 0"/>
    <axis xyz="0 0 1"/>
    <!-- ====== for Gazebo  ======  -->
    <limit effort="30" lower="-1.3" upper="1.3" velocity="1.571"/>
    <dynamics damping="0.7"/>
    <!-- == == == == == == == == == -->
  </joint>
  <link name="link4">
    <visual>
      <geometry>
        <mesh filename="package://snakebot_description/meshes/DAE/pitch_motor_link2.dae"/>
      </geometry>
    </visual>
    <!-- ====== for Gazebo ====== -->
    <collision>
      <geometry>
        <mesh filename="package://snakebot_description/meshes/DAE/pitch_motor_link2.dae"/>
      </geometry>
    </collision>
    <inertial>
      <mass value="0.1"/>
      <inertia ixx="1.0" ixy="0.0" ixz="0.0" iyy="1.0" iyz="0.0" izz="1.0"/>
    </inertial>
    <!-- == == == == == == == == == -->
  </link>
  <joint name="joint5" type="revolute">
    <parent link="link4"/>
    <child link="link5"/>
    <origin xyz="-0.09 0 0"/>
    <axis xyz="0 1 0"/>
    <!-- ====== for Gazebo  ======  -->
    <limit effort="30" lower="-1.3" upper="1.3" velocity="1.571"/>
    <dynamics damping="0.7"/>
    <!-- == == == == == == == == == -->
  </joint>
  <link name="link5">
    <visual>
      <geometry>
        <mesh filename="package://snakebot_description/meshes/DAE/yaw_motor_link2.dae"/>
      </geometry>
    </visual>
    <!-- ====== for Gazebo ====== -->
    <collision>
      <geometry>
        <mesh filename="package://snakebot_description/meshes/DAE/yaw_motor_link2.dae"/>
      </geometry>
    </collision>
    <inertial>
      <mass value="0.1"/>
      <inertia ixx="1.0" ixy="0.0" ixz="0.0" iyy="1.0" iyz="0.0" izz="1.0"/>
    </inertial>
    <!-- == == == == == == == == == -->
  </link>
  <joint name="joint6" type="revolute">
    <parent link="link5"/>
    <child link="link6"/>
    <origin xyz="-0.09 0 0"/>
    <axis xyz="0 0 1"/>
    <!-- ====== for Gazebo  ======  -->
    <limit effort="30" lower="-1.3" upper="1.3" velocity="1.571"/>
    <dynamics damping="0.7"/>
    <!-- == == == == == == == == == -->
  </joint>
  <link name="link6">
    <visual>
      <geometry>
        <mesh filename="package://snakebot_description/meshes/DAE/pitch_motor_link2.dae"/>
      </geometry>
    </visual>
    <!-- ====== for Gazebo ====== -->
    <collision>
      <geometry>
        <mesh filename="package://snakebot_description/meshes/DAE/pitch_motor_link2.dae"/>
      </geometry>
    </collision>
    <inertial>
      <mass value="0.1"/>
      <inertia ixx="1.0" ixy="0.0" ixz="0.0" iyy="1.0" iyz="0.0" izz="1.0"/>
    </inertial>
    <!-- == == == == == == == == == -->
  </link>
  <joint name="joint7" type="revolute">
    <parent link="link6"/>
    <child link="link7"/>
    <origin xyz="-0.09 0 0"/>
    <axis xyz="0 1 0"/>
    <!-- ====== for Gazebo  ======  -->
    <limit effort="30" lower="-1.3" upper="1.3" velocity="1.571"/>
    <dynamics damping="0.7"/>
    <!-- == == == == == == == == == -->
  </joint>
  <link name="link7">
    <visual>
      <geometry>
        <mesh filename="package://snakebot_description/meshes/DAE/yaw_motor_link2.dae"/>
      </geometry>
    </visual>
    <!-- ====== for Gazebo ====== -->
    <collision>
      <geometry>
        <mesh filename="package://snakebot_description/meshes/DAE/yaw_motor_link2.dae"/>
      </geometry>
    </collision>
    <inertial>
      <mass value="0.1"/>
      <inertia ixx="1.0" ixy="0.0" ixz="0.0" iyy="1.0" iyz="0.0" izz="1.0"/>
    </inertial>
    <!-- == == == == == == == == == -->
  </link>
  <joint name="joint8" type="revolute">
    <parent link="link7"/>
    <child link="link8"/>
    <origin xyz="-0.09 0 0"/>
    <axis xyz="0 0 1"/>
    <!-- ====== for Gazebo  ======  -->
    <limit effort="30" lower="-1.3" upper="1.3" velocity="1.571"/>
    <dynamics damping="0.7"/>
    <!-- == == == == == == == == == -->
  </joint>
  <link name="link8">
    <visual>
      <geometry>
        <mesh filename="package://snakebot_description/meshes/DAE/pitch_motor_link2.dae"/>
      </geometry>
    </visual>
    <!-- ====== for Gazebo ====== -->
    <collision>
      <geometry>
        <mesh filename="package://snakebot_description/meshes/DAE/pitch_motor_link2.dae"/>
      </geometry>
    </collision>
    <inertial>
      <mass value="0.1"/>
      <inertia ixx="1.0" ixy="0.0" ixz="0.0" iyy="1.0" iyz="0.0" izz="1.0"/>
    </inertial>
    <!-- == == == == == == == == == -->
  </link>
  <joint name="joint9" type="revolute">
    <parent link="link8"/>
    <child link="link9"/>
    <origin xyz="-0.09 0 0"/>
    <axis xyz="0 1 0"/>
    <!-- ====== for Gazebo  ======  -->
    <limit effort="30" lower="-1.3" upper="1.3" velocity="1.571"/>
    <dynamics damping="0.7"/>
    <!-- == == == == == == == == == -->
  </joint>
  <link name="link9">
    <visual>
      <geometry>
        <mesh filename="package://snakebot_description/meshes/DAE/yaw_motor_link2.dae"/>
      </geometry>
    </visual>
    <!-- ====== for Gazebo ====== -->
    <collision>
      <geometry>
        <mesh filename="package://snakebot_description/meshes/DAE/yaw_motor_link2.dae"/>
      </geometry>
    </collision>
    <inertial>
      <mass value="0.1"/>
      <inertia ixx="1.0" ixy="0.0" ixz="0.0" iyy="1.0" iyz="0.0" izz="1.0"/>
    </inertial>
    <!-- == == == == == == == == == -->
  </link>
  <joint name="joint10" type="revolute">
    <parent link="link9"/>
    <child link="link10"/>
    <origin xyz="-0.09 0 0"/>
    <axis xyz="0 0 1"/>
    <!-- ====== for Gazebo  ======  -->
    <limit effort="30" lower="-1.3" upper="1.3" velocity="1.571"/>
    <dynamics damping="0.7"/>
    <!-- == == == == == == == == == -->
  </joint>
  <link name="link10">
    <visual>
      <geometry>
        <mesh filename="package://snakebot_description/meshes/DAE/pitch_motor_link2.dae"/>
      </geometry>
    </visual>
    <!-- ====== for Gazebo ====== -->
    <collision>
      <geometry>
        <mesh filename="package://snakebot_description/meshes/DAE/pitch_motor_link2.dae"/>
      </geometry>
    </collision>
    <inertial>
      <mass value="0.1"/>
      <inertia ixx="1.0" ixy="0.0" ixz="0.0" iyy="1.0" iyz="0.0" izz="1.0"/>
    </inertial>
    <!-- == == == == == == == == == -->
  </link>
  <joint name="joint11" type="revolute">
    <parent link="link10"/>
    <child link="link11"/>
    <origin xyz="-0.09 0 0"/>
    <axis xyz="0 1 0"/>
    <!-- ====== for Gazebo  ======  -->
    <limit effort="30" lower="-1.3" upper="1.3" velocity="1.571"/>
    <dynamics damping="0.7"/>
    <!-- == == == == == == == == == -->
  </joint>
  <link name="link11">
    <visual>
      <geometry>
        <mesh filename="package://snakebot_description/meshes/DAE/yaw_motor_link2.dae"/>
      </geometry>
    </visual>
    <!-- ====== for Gazebo ====== -->
    <collision>
      <geometry>
        <mesh filename="package://snakebot_description/meshes/DAE/yaw_motor_link2.dae"/>
      </geometry>
    </collision>
    <inertial>
      <mass value="0.1"/>
      <inertia ixx="1.0" ixy="0.0" ixz="0.0" iyy="1.0" iyz="0.0" izz="1.0"/>
    </inertial>
    <!-- == == == == == == == == == -->
  </link>
  <joint name="joint12" type="revolute">
    <parent link="link11"/>
    <child link="link12"/>
    <origin xyz="-0.09 0 0"/>
    <axis xyz="0 0 1"/>
    <!-- ====== for Gazebo  ======  -->
    <limit effort="30" lower="-1.3" upper="1.3" velocity="1.571"/>
    <dynamics damping="0.7"/>
    <!-- == == == == == == == == == -->
  </joint>
  <link name="link12">
    <visual>
      <geometry>
        <mesh filename="package://snakebot_description/meshes/DAE/pitch_motor_link2.dae"/>
      </geometry>
    </visual>
    <!-- ====== for Gazebo ====== -->
    <collision>
      <geometry>
        <mesh filename="package://snakebot_description/meshes/DAE/pitch_motor_link2.dae"/>
      </geometry>
    </collision>
    <inertial>
      <mass value="0.1"/>
      <inertia ixx="1.0" ixy="0.0" ixz="0.0" iyy="1.0" iyz="0.0" izz="1.0"/>
    </inertial>
    <!-- == == == == == == == == == -->
  </link>
  <joint name="joint13" type="revolute">
    <parent link="link12"/>
    <child link="link13"/>
    <origin xyz="-0.09 0 0"/>
    <axis xyz="0 1 0"/>
    <!-- ====== for Gazebo  ======  -->
    <limit effort="30" lower="-1.3" upper="1.3" velocity="1.571"/>
    <dynamics damping="0.7"/>
    <!-- == == == == == == == == == -->
  </joint>
  <link name="link13">
    <visual>
      <geometry>
        <mesh filename="package://snakebot_description/meshes/DAE/yaw_motor_link2.dae"/>
      </geometry>
    </visual>
    <!-- ====== for Gazebo ====== -->
    <collision>
      <geometry>
        <mesh filename="package://snakebot_description/meshes/DAE/yaw_motor_link2.dae"/>
      </geometry>
    </collision>
    <inertial>
      <mass value="0.1"/>
      <inertia ixx="1.0" ixy="0.0" ixz="0.0" iyy="1.0" iyz="0.0" izz="1.0"/>
    </inertial>
    <!-- == == == == == == == == == -->
  </link>
  <joint name="joint14" type="revolute">
    <parent link="link13"/>
    <child link="link14"/>
    <origin xyz="-0.09 0 0"/>
    <axis xyz="0 0 1"/>
    <!-- ====== for Gazebo  ======  -->
    <limit effort="30" lower="-1.3" upper="1.3" velocity="1.571"/>
    <dynamics damping="0.7"/>
    <!-- == == == == == == == == == -->
  </joint>
  <link name="link14">
    <visual>
      <geometry>
        <mesh filename="package://snakebot_description/meshes/DAE/pitch_motor_link2.dae"/>
      </geometry>
    </visual>
    <!-- ====== for Gazebo ====== -->
    <collision>
      <geometry>
        <mesh filename="package://snakebot_description/meshes/DAE/pitch_motor_link2.dae"/>
      </geometry>
    </collision>
    <inertial>
      <mass value="0.1"/>
      <inertia ixx="1.0" ixy="0.0" ixz="0.0" iyy="1.0" iyz="0.0" izz="1.0"/>
    </inertial>
    <!-- == == == == == == == == == -->
  </link>
  <joint name="joint15" type="revolute">
    <parent link="link14"/>
    <child link="link15"/>
    <origin xyz="-0.09 0 0"/>
    <axis xyz="0 1 0"/>
    <!-- ====== for Gazebo  ======  -->
    <limit effort="30" lower="-1.3" upper="1.3" velocity="1.571"/>
    <dynamics damping="0.7"/>
    <!-- == == == == == == == == == -->
  </joint>
  <link name="link15">
    <visual>
      <geometry>
        <mesh filename="package://snakebot_description/meshes/DAE/yaw_motor_link2.dae"/>
      </geometry>
    </visual>
    <!-- ====== for Gazebo ====== -->
    <collision>
      <geometry>
        <mesh filename="package://snakebot_description/meshes/DAE/yaw_motor_link2.dae"/>
      </geometry>
    </collision>
    <inertial>
      <mass value="0.1"/>
      <inertia ixx="1.0" ixy="0.0" ixz="0.0" iyy="1.0" iyz="0.0" izz="1.0"/>
    </inertial>
    <!-- == == == == == == == == == -->
  </link>
  <joint name="joint16" type="revolute">
    <parent link="link15"/>
    <child link="link16"/>
    <origin xyz="-0.09 0 0"/>
    <axis xyz="0 0 1"/>
    <!-- ====== for Gazebo  ======  -->
    <limit effort="30" lower="-1.3" upper="1.3" velocity="1.571"/>
    <dynamics damping="0.7"/>
    <!-- == == == == == == == == == -->
  </joint>
  <link name="link16">
    <visual>
      <geometry>
        <mesh filename="package://snakebot_description/meshes/DAE/pitch_motor_link2.dae"/>
      </geometry>
    </visual>
    <!-- ====== for Gazebo ====== -->
    <collision>
      <geometry>
        <mesh filename="package://snakebot_description/meshes/DAE/pitch_motor_link2.dae"/>
      </geometry>
    </collision>
    <inertial>
      <mass value="0.1"/>
      <inertia ixx="1.0" ixy="0.0" ixz="0.0" iyy="1.0" iyz="0.0" izz="1.0"/>
    </inertial>
    <!-- == == == == == == == == == -->
  </link>
  <joint name="joint17" type="revolute">
    <parent link="link16"/>
    <child link="link17"/>
    <origin xyz="-0.09 0 0"/>
    <axis xyz="0 1 0"/>
    <!-- ====== for Gazebo  ======  -->
    <limit effort="30" lower="-1.3" upper="1.3" velocity="1.571"/>
    <dynamics damping="0.7"/>
    <!-- == == == == == == == == == -->
  </joint>
  <link name="link17">
    <visual>
      <geometry>
        <mesh filename="package://snakebot_description/meshes/DAE/yaw_motor_link2.dae"/>
      </geometry>
    </visual>
    <!-- ====== for Gazebo ====== -->
    <collision>
      <geometry>
        <mesh filename="package://snakebot_description/meshes/DAE/yaw_motor_link2.dae"/>
      </geometry>
    </collision>
    <inertial>
      <mass value="0.1"/>
      <inertia ixx="1.0" ixy="0.0" ixz="0.0" iyy="1.0" iyz="0.0" izz="1.0"/>
    </inertial>
    <!-- == == == == == == == == == -->
  </link>
  <joint name="joint18" type="revolute">
    <parent link="link17"/>
    <child link="link18"/>
    <origin xyz="-0.09 0 0"/>
    <axis xyz="0 0 1"/>
    <!-- ====== for Gazebo  ======  -->
    <limit effort="30" lower="-1.3" upper="1.3" velocity="1.571"/>
    <dynamics damping="0.7"/>
    <!-- == == == == == == == == == -->
  </joint>
  <link name="link18">
    <visual>
      <geometry>
        <mesh filename="package://snakebot_description/meshes/DAE/pitch_motor_link2.dae"/>
      </geometry>
    </visual>
    <!-- ====== for Gazebo ====== -->
    <collision>
      <geometry>
        <mesh filename="package://snakebot_description/meshes/DAE/pitch_motor_link2.dae"/>
      </geometry>
    </collision>
    <inertial>
      <mass value="0.1"/>
      <inertia ixx="1.0" ixy="0.0" ixz="0.0" iyy="1.0" iyz="0.0" izz="1.0"/>
    </inertial>
    <!-- == == == == == == == == == -->
  </link>
  <!-- <xacro:snakebot_joint index="21" pl_index="20" isPitch="true"/> -->
  <!-- <xacro:snakebot_link index="21" isHead="false" isMotorLink="false"/>-->
  <!-- <xacro:snakebot_joint index="22" pl_index="21" isPitch="false"/> -->
  <!-- <xacro:snakebot_link index="22" isHead="false" isMotorLink="true"/> -->
  <!-- <xacro:snakebot_joint index="23" pl_index="22" isPitch="true"/> -->
  <!-- <xacro:snakebot_link index="23" isHead="false" isMotorLink="false"/> -->
  <!-- <xacro:snakebot_joint index="24" pl_index="23" isPitch="false"/> -->
  <!-- <xacro:snakebot_link index="24" isHead="false" isMotorLink="true"/> -->
  <!-- <xacro:snakebot_joint index="25" pl_index="24" isPitch="true"/> -->
  <!-- <xacro:snakebot_link index="25" isHead="false" isMotorLink="false"/> -->
  <!-- <xacro:snakebot_joint index="26" pl_index="25" isPitch="false"/> -->
  <!-- <xacro:snakebot_link index="26" isHead="false" isMotorLink="true"/> -->
  <!-- <xacro:snakebot_joint index="27" pl_index="26" isPitch="true"/> -->
  <!-- <xacro:snakebot_link index="27" isHead="false" isMotorLink="false"/> -->
  <!-- <xacro:snakebot_joint index="28" pl_index="27" isPitch="false"/> -->
  <!-- <xacro:snakebot_link index="28" isHead="false" isMotorLink="true"/> -->
  <!-- <xacro:snakebot_joint index="29" pl_index="28" isPitch="true"/> -->
  <!-- <xacro:snakebot_link index="29" isHead="false" isMotorLink="false"/> -->
  <!-- <xacro:snakebot_joint index="30" pl_index="29" isPitch="false"/> -->
  <!-- <xacro:snakebot_link index="30" isHead="false" isMotorLink="true"/> -->
  <!-- tail unit must be here -->
  <!-- =============== Gazebo =============== -->
  <gazebo>
    <plugin filename="libgazebo_ros_control.so" name="gazebo_ros_control">
      <robotNamespace>snakebot</robotNamespace>
      <robotSimType>gazebo_ros_control/DefaultRobotHWSim</robotSimType>
    </plugin>
  </gazebo>
  <gazebo reference="camera_link">
    <selfCollide>true</selfCollide>
    <mu1 value="0.05"/>
    <mu2 value="0.05"/>
  </gazebo>
  <transmission name="tran_camera">
    <type>transmission_interface/SimpleTransmission</type>
    <joint name="joint0">
      <hardwareInterface>EffortJointInterface</hardwareInterface>
    </joint>
    <actuator name="motor_camera">
      <hardwareInterface>EffortJointInterface</hardwareInterface>
      <mechanicalReduction>1</mechanicalReduction>
    </actuator>
  </transmission>
  <!-- body units -->
  <gazebo reference="link1">
    <selfCollide>true</selfCollide>
    <mu1 value="0.05"/>
    <mu2 value="0.05"/>
  </gazebo>
  <transmission name="tran1">
    <type>transmission_interface/SimpleTransmission</type>
    <joint name="joint1">
      <hardwareInterface>EffortJointInterface</hardwareInterface>
    </joint>
    <actuator name="{motor_name}1">
      <hardwareInterface>EffortJointInterface</hardwareInterface>
      <mechanicalReduction>1</mechanicalReduction>
    </actuator>
  </transmission>
  <gazebo reference="link2">
    <selfCollide>true</selfCollide>
    <mu1 value="0.05"/>
    <mu2 value="0.05"/>
  </gazebo>
  <transmission name="tran2">
    <type>transmission_interface/SimpleTransmission</type>
    <joint name="joint2">
      <hardwareInterface>EffortJointInterface</hardwareInterface>
    </joint>
    <actuator name="{motor_name}2">
      <hardwareInterface>EffortJointInterface</hardwareInterface>
      <mechanicalReduction>1</mechanicalReduction>
    </actuator>
  </transmission>
  <gazebo reference="link3">
    <selfCollide>true</selfCollide>
    <mu1 value="0.05"/>
    <mu2 value="0.05"/>
  </gazebo>
  <transmission name="tran3">
    <type>transmission_interface/SimpleTransmission</type>
    <joint name="joint3">
      <hardwareInterface>EffortJointInterface</hardwareInterface>
    </joint>
    <actuator name="{motor_name}3">
      <hardwareInterface>EffortJointInterface</hardwareInterface>
      <mechanicalReduction>1</mechanicalReduction>
    </actuator>
  </transmission>
  <gazebo reference="link4">
    <selfCollide>true</selfCollide>
    <mu1 value="0.05"/>
    <mu2 value="0.05"/>
  </gazebo>
  <transmission name="tran4">
    <type>transmission_interface/SimpleTransmission</type>
    <joint name="joint4">
      <hardwareInterface>EffortJointInterface</hardwareInterface>
    </joint>
    <actuator name="{motor_name}4">
      <hardwareInterface>EffortJointInterface</hardwareInterface>
      <mechanicalReduction>1</mechanicalReduction>
    </actuator>
  </transmission>
  <gazebo reference="link5">
    <selfCollide>true</selfCollide>
    <mu1 value="0.05"/>
    <mu2 value="0.05"/>
  </gazebo>
  <transmission name="tran5">
    <type>transmission_interface/SimpleTransmission</type>
    <joint name="joint5">
      <hardwareInterface>EffortJointInterface</hardwareInterface>
    </joint>
    <actuator name="{motor_name}5">
      <hardwareInterface>EffortJointInterface</hardwareInterface>
      <mechanicalReduction>1</mechanicalReduction>
    </actuator>
  </transmission>
  <gazebo reference="link6">
    <selfCollide>true</selfCollide>
    <mu1 value="0.05"/>
    <mu2 value="0.05"/>
  </gazebo>
  <transmission name="tran6">
    <type>transmission_interface/SimpleTransmission</type>
    <joint name="joint6">
      <hardwareInterface>EffortJointInterface</hardwareInterface>
    </joint>
    <actuator name="{motor_name}6">
      <hardwareInterface>EffortJointInterface</hardwareInterface>
      <mechanicalReduction>1</mechanicalReduction>
    </actuator>
  </transmission>
  <gazebo reference="link7">
    <selfCollide>true</selfCollide>
    <mu1 value="0.05"/>
    <mu2 value="0.05"/>
  </gazebo>
  <transmission name="tran7">
    <type>transmission_interface/SimpleTransmission</type>
    <joint name="joint7">
      <hardwareInterface>EffortJointInterface</hardwareInterface>
    </joint>
    <actuator name="{motor_name}7">
      <hardwareInterface>EffortJointInterface</hardwareInterface>
      <mechanicalReduction>1</mechanicalReduction>
    </actuator>
  </transmission>
  <gazebo reference="link8">
    <selfCollide>true</selfCollide>
    <mu1 value="0.05"/>
    <mu2 value="0.05"/>
  </gazebo>
  <transmission name="tran8">
    <type>transmission_interface/SimpleTransmission</type>
    <joint name="joint8">
      <hardwareInterface>EffortJointInterface</hardwareInterface>
    </joint>
    <actuator name="{motor_name}8">
      <hardwareInterface>EffortJointInterface</hardwareInterface>
      <mechanicalReduction>1</mechanicalReduction>
    </actuator>
  </transmission>
  <gazebo reference="link9">
    <selfCollide>true</selfCollide>
    <mu1 value="0.05"/>
    <mu2 value="0.05"/>
  </gazebo>
  <transmission name="tran9">
    <type>transmission_interface/SimpleTransmission</type>
    <joint name="joint9">
      <hardwareInterface>EffortJointInterface</hardwareInterface>
    </joint>
    <actuator name="{motor_name}9">
      <hardwareInterface>EffortJointInterface</hardwareInterface>
      <mechanicalReduction>1</mechanicalReduction>
    </actuator>
  </transmission>
  <gazebo reference="link10">
    <selfCollide>true</selfCollide>
    <mu1 value="0.05"/>
    <mu2 value="0.05"/>
  </gazebo>
  <transmission name="tran10">
    <type>transmission_interface/SimpleTransmission</type>
    <joint name="joint10">
      <hardwareInterface>EffortJointInterface</hardwareInterface>
    </joint>
    <actuator name="{motor_name}10">
      <hardwareInterface>EffortJointInterface</hardwareInterface>
      <mechanicalReduction>1</mechanicalReduction>
    </actuator>
  </transmission>
  <gazebo reference="link11">
    <selfCollide>true</selfCollide>
    <mu1 value="0.05"/>
    <mu2 value="0.05"/>
  </gazebo>
  <transmission name="tran11">
    <type>transmission_interface/SimpleTransmission</type>
    <joint name="joint11">
      <hardwareInterface>EffortJointInterface</hardwareInterface>
    </joint>
    <actuator name="{motor_name}11">
      <hardwareInterface>EffortJointInterface</hardwareInterface>
      <mechanicalReduction>1</mechanicalReduction>
    </actuator>
  </transmission>
  <gazebo reference="link12">
    <selfCollide>true</selfCollide>
    <mu1 value="0.05"/>
    <mu2 value="0.05"/>
  </gazebo>
  <transmission name="tran12">
    <type>transmission_interface/SimpleTransmission</type>
    <joint name="joint12">
      <hardwareInterface>EffortJointInterface</hardwareInterface>
    </joint>
    <actuator name="{motor_name}12">
      <hardwareInterface>EffortJointInterface</hardwareInterface>
      <mechanicalReduction>1</mechanicalReduction>
    </actuator>
  </transmission>
  <gazebo reference="link13">
    <selfCollide>true</selfCollide>
    <mu1 value="0.05"/>
    <mu2 value="0.05"/>
  </gazebo>
  <transmission name="tran13">
    <type>transmission_interface/SimpleTransmission</type>
    <joint name="joint13">
      <hardwareInterface>EffortJointInterface</hardwareInterface>
    </joint>
    <actuator name="{motor_name}13">
      <hardwareInterface>EffortJointInterface</hardwareInterface>
      <mechanicalReduction>1</mechanicalReduction>
    </actuator>
  </transmission>
  <gazebo reference="link14">
    <selfCollide>true</selfCollide>
    <mu1 value="0.05"/>
    <mu2 value="0.05"/>
  </gazebo>
  <transmission name="tran14">
    <type>transmission_interface/SimpleTransmission</type>
    <joint name="joint14">
      <hardwareInterface>EffortJointInterface</hardwareInterface>
    </joint>
    <actuator name="{motor_name}14">
      <hardwareInterface>EffortJointInterface</hardwareInterface>
      <mechanicalReduction>1</mechanicalReduction>
    </actuator>
  </transmission>
  <gazebo reference="link15">
    <selfCollide>true</selfCollide>
    <mu1 value="0.05"/>
    <mu2 value="0.05"/>
  </gazebo>
  <transmission name="tran15">
    <type>transmission_interface/SimpleTransmission</type>
    <joint name="joint15">
      <hardwareInterface>EffortJointInterface</hardwareInterface>
    </joint>
    <actuator name="{motor_name}15">
      <hardwareInterface>EffortJointInterface</hardwareInterface>
      <mechanicalReduction>1</mechanicalReduction>
    </actuator>
  </transmission>
  <gazebo reference="link16">
    <selfCollide>true</selfCollide>
    <mu1 value="0.05"/>
    <mu2 value="0.05"/>
  </gazebo>
  <transmission name="tran16">
    <type>transmission_interface/SimpleTransmission</type>
    <joint name="joint16">
      <hardwareInterface>EffortJointInterface</hardwareInterface>
    </joint>
    <actuator name="{motor_name}16">
      <hardwareInterface>EffortJointInterface</hardwareInterface>
      <mechanicalReduction>1</mechanicalReduction>
    </actuator>
  </transmission>
  <gazebo reference="link17">
    <selfCollide>true</selfCollide>
    <mu1 value="0.05"/>
    <mu2 value="0.05"/>
  </gazebo>
  <transmission name="tran17">
    <type>transmission_interface/SimpleTransmission</type>
    <joint name="joint17">
      <hardwareInterface>EffortJointInterface</hardwareInterface>
    </joint>
    <actuator name="{motor_name}17">
      <hardwareInterface>EffortJointInterface</hardwareInterface>
      <mechanicalReduction>1</mechanicalReduction>
    </actuator>
  </transmission>
  <gazebo reference="link18">
    <selfCollide>true</selfCollide>
    <mu1 value="0.05"/>
    <mu2 value="0.05"/>
  </gazebo>
  <transmission name="tran18">
    <type>transmission_interface/SimpleTransmission</type>
    <joint name="joint18">
      <hardwareInterface>EffortJointInterface</hardwareInterface>
    </joint>
    <actuator name="{motor_name}18">
      <hardwareInterface>EffortJointInterface</hardwareInterface>
      <mechanicalReduction>1</mechanicalReduction>
    </actuator>
  </transmission>
  <gazebo reference="link19">
    <selfCollide>true</selfCollide>
    <mu1 value="0.05"/>
    <mu2 value="0.05"/>
  </gazebo>
  <transmission name="tran19">
    <type>transmission_interface/SimpleTransmission</type>
    <joint name="joint19">
      <hardwareInterface>EffortJointInterface</hardwareInterface>
    </joint>
    <actuator name="{motor_name}19">
      <hardwareInterface>EffortJointInterface</hardwareInterface>
      <mechanicalReduction>1</mechanicalReduction>
    </actuator>
  </transmission>
  <!-- <xacro:link_num index="21"/> -->
  <!-- <xacro:link_num index="22"/> -->
  <!-- <xacro:link_num index="23"/> -->
  <!-- <xacro:link_num index="24"/> -->
  <!-- <xacro:link_num index="25"/> -->
  <!-- <xacro:link_num index="26"/> -->
  <!-- <xacro:link_num index="27"/> -->
  <!-- <xacro:link_num index="28"/> -->
  <!-- <xacro:link_num index="29"/> -->
  <!-- <xacro:link_num index="30"/> -->
</robot>

